<?xml version='1.0'?>

<robot name="my_robot" xmlns:xacro="http://www.ros.org/wiki/xacro">

  <link name="robot_footprint"></link>

  <joint name="robot_footprint_joint" type="fixed">
    <origin xyz="0 0 0" rpy="0 0 0" />
    <parent link="robot_footprint"/>
    <child link="chassis" />
  </joint>

  <link name="chassis">
    <pose>0 0 0.1 0 0 0</pose>

    <inertial>
      <mass value="15.0"/>
      <origin xyz="0.0 0 0" rpy=" 0 0 0"/>
      <inertia
          ixx="0.15" ixy="0" ixz="0"
          iyy="0.15" iyz="0"
          izz="0.2"
      />
    </inertial>

    <collision name="collision">
      <origin xyz="0 0 0" rpy=" 0 0 0"/> 
      <geometry>
        <cylinder radius="0.2" length="0.1"/>
      </geometry>
    </collision>

    <visual name="chassis_visual">
      <origin xyz="0 0 0" rpy=" 0 0 0"/>
      <geometry>
        <cylinder radius="0.2" length="0.1"/>
      </geometry>
      <material name="chassis_color">
        <color rgba="0.5 0.5 0.5 1.0"/> <!-- Gray color -->
      </material>
    </visual>
  </link>

  <!-- Front Caster -->
  <link name="front_caster">
    <inertial>
      <mass value="0.5"/>
      <origin xyz="0 0 0" rpy="0 0 0"/>
      <inertia
          ixx="0.01" ixy="0" ixz="0"
          iyy="0.01" iyz="0"
          izz="0.01"
      />
    </inertial>
    <collision>
      <geometry>
        <sphere radius="0.05"/>
      </geometry>
    </collision>
    <visual>
      <geometry>
        <sphere radius="0.05"/>
      </geometry>
      <material name="caster_color">
        <color rgba="0.8 0.2 0.2 1.0"/> <!-- Red color -->
      </material>
    </visual>
  </link>

  <joint name="front_caster_joint" type="fixed">
    <origin xyz="0.15 0 -0.05" rpy="0 0 0"/>
    <parent link="chassis"/>
    <child link="front_caster"/>
  </joint>

   <!-- Camera Link -->
  <link name="camera">
    <inertial>
      <mass value="0.1"/>
      <origin xyz="0 0 0" rpy="0 0 0"/>
      <inertia
          ixx="1e-6" ixy="0" ixz="0"
          iyy="1e-6" iyz="0"
          izz="1e-6"
      />
    </inertial>
    <collision>
      <origin xyz="0 0 0" rpy="0 0 0"/>
      <geometry>
        <box size="0.05 0.05 0.05"/>
      </geometry>
    </collision>
    <visual>
      <origin xyz="0 0 0" rpy="0 0 0"/>
      <geometry>
        <box size="0.05 0.05 0.05"/>
      </geometry>
      <material name="camera_color">
        <color rgba="0.2 0.8 0.2 1.0"/> <!-- Green color -->
      </material>
    </visual>
  </link>

  <!-- Camera Joint -->
  <joint name="camera_joint" type="fixed">
    <origin xyz="0.2 0 0" rpy="0 0 0"/>
    <parent link="chassis"/>
    <child link="camera"/>
    <axis xyz="0 1 0"/>
  </joint>

   <!-- Hokuyo Link -->
  <link name="hokuyo">
    <inertial>
      <mass value="1e-5"/>
      <origin xyz="0 0 0" rpy="0 0 0"/>
      <inertia
          ixx="1e-6" ixy="0" ixz="0"
          iyy="1e-6" iyz="0"
          izz="1e-6"
      />
    </inertial>
    <collision>
      <origin xyz="0 0 0" rpy="0 0 0"/>
      <geometry>
        <box size="0.1 0.1 0.1"/>
      </geometry>
    </collision>
    <visual>
      <origin xyz="0 0 0" rpy="0 0 0"/>
      <geometry>
        <mesh filename="package://my_robot/meshes/hokuyo.dae"/>
      </geometry>
      <material name="hokuyo_color">
        <color rgba="0.2 0.2 0.2 1.0"/> <!-- Dark Gray -->
      </material>
    </visual>
  </link>

  <!-- Hokuyo Joint -->
  <joint name="hokuyo_joint" type="fixed">
    <origin xyz="0.15 0 0.085" rpy="0 0 0"/>
    <parent link="chassis"/>
    <child link="hokuyo"/>
    <axis xyz="0 1 0"/>
  </joint>


  <!-- Left Wheel -->
  <link name="left_wheel">
    <inertial>
      <mass value="0.5"/>
      <origin xyz="0 0 0" rpy="0 0 0"/>
      <inertia
          ixx="0.02" ixy="0" ixz="0"
          iyy="0.02" iyz="0"
          izz="0.03"
      />
    </inertial>
    <collision>
      <origin xyz="0 0 0" rpy="1.5707 0 0"/>
      <geometry>
        <cylinder radius="0.08" length="0.02"/>
      </geometry>
    </collision>
    <visual>
      <origin xyz="0 0 0" rpy="1.5707 0 0"/>
      <geometry>
        <cylinder radius="0.08" length="0.02"/>
      </geometry>
      <material name="wheel_color">
        <color rgba="0.2 0.2 0.8 1.0"/> <!-- Blue color -->
      </material>
    </visual>
  </link>

 
  <joint type="continuous" name="left_wheel_joint">
    <origin xyz="-0.1 -0.2 0" rpy="0 0 0"/> <!-- Pinned to chassis edge -->
    <child link="left_wheel"/>
    <parent link="chassis"/>
    <axis xyz="0 1 0" rpy="0 0 0"/>
    <limit effort="10000" velocity="1000"/>
    <dynamics damping="1.0" friction="1.0"/>
  </joint>

  <!-- Right Wheel -->
  <link name="right_wheel">
    <inertial>
      <mass value="0.5"/>
      <origin xyz="0 0 0" rpy="0 0 0"/>
      <inertia
          ixx="0.02" ixy="0" ixz="0"
          iyy="0.02" iyz="0"
          izz="0.03"
      />
    </inertial>
    <collision>
      <origin xyz="0 0 0" rpy="1.5707 0 0"/>
      <geometry>
        <cylinder radius="0.08" length="0.02"/>
      </geometry>
    </collision>
    <visual>
      <origin xyz="0 0 0" rpy="1.5707 0 0"/>
      <geometry>
        <cylinder radius="0.08" length="0.02"/>
      </geometry>
    </visual>
  </link>

 
  <joint type="continuous" name="right_wheel_joint">
    <origin xyz="-0.1 0.2 0" rpy="0 0 0"/> <!-- Pinned to chassis edge -->
    <child link="right_wheel"/>
    <parent link="chassis"/>
    <axis xyz="0 1 0" rpy="0 0 0"/>
    <limit effort="10000" velocity="1000"/>
    <dynamics damping="1.0" friction="1.0"/>
  </joint>


  <gazebo reference="chassis">

	<material>Gazebo/Blue</material>

  </gazebo>

  <gazebo reference="camera">

	<material>Gazebo/Red</material>

  </gazebo>

  <gazebo reference="left_wheel">

	<material>Gazebo/Green</material>

   </gazebo>

   <gazebo reference="right_wheel">

	<material>Gazebo/Green</material>

   </gazebo>
  

   <gazebo reference="front_caster">

	<material>Gazebo/Yellow</material>

   </gazebo>
</robot>

